[2024-12-05T10:41:37.905+0000] {local_task_job_runner.py:123} INFO - ::group::Pre task execution logs
[2024-12-05T10:41:37.924+0000] {taskinstance.py:2613} INFO - Dependencies all met for dep_context=non-requeueable deps ti=<TaskInstance: bigquery_etl_dag.load_and_transform_data manual__2024-12-05T10:41:35.577441+00:00 [queued]>
[2024-12-05T10:41:37.933+0000] {taskinstance.py:2613} INFO - Dependencies all met for dep_context=requeueable deps ti=<TaskInstance: bigquery_etl_dag.load_and_transform_data manual__2024-12-05T10:41:35.577441+00:00 [queued]>
[2024-12-05T10:41:37.934+0000] {taskinstance.py:2866} INFO - Starting attempt 1 of 2
[2024-12-05T10:41:37.949+0000] {taskinstance.py:2889} INFO - Executing <Task(PythonOperator): load_and_transform_data> on 2024-12-05 10:41:35.577441+00:00
[2024-12-05T10:41:37.956+0000] {warnings.py:112} WARNING - /home/***/.local/lib/python3.12/site-packages/***/task/task_runner/standard_task_runner.py:70: DeprecationWarning: This process (pid=737) is multi-threaded, use of fork() may lead to deadlocks in the child.
  pid = os.fork()

[2024-12-05T10:41:37.958+0000] {standard_task_runner.py:104} INFO - Running: ['***', 'tasks', 'run', 'bigquery_etl_dag', 'load_and_transform_data', 'manual__2024-12-05T10:41:35.577441+00:00', '--job-id', '118', '--raw', '--subdir', 'DAGS_FOLDER/bigquery_etl_dag.py', '--cfg-path', '/tmp/tmp7o60keqf']
[2024-12-05T10:41:37.960+0000] {standard_task_runner.py:72} INFO - Started process 739 to run task
[2024-12-05T10:41:37.960+0000] {standard_task_runner.py:105} INFO - Job 118: Subtask load_and_transform_data
[2024-12-05T10:41:38.012+0000] {task_command.py:467} INFO - Running <TaskInstance: bigquery_etl_dag.load_and_transform_data manual__2024-12-05T10:41:35.577441+00:00 [running]> on host af08a0babd6a
[2024-12-05T10:41:38.098+0000] {taskinstance.py:3132} INFO - Exporting env vars: AIRFLOW_CTX_DAG_EMAIL='arbenos20@gmail.com' AIRFLOW_CTX_DAG_OWNER='***' AIRFLOW_CTX_DAG_ID='bigquery_etl_dag' AIRFLOW_CTX_TASK_ID='load_and_transform_data' AIRFLOW_CTX_EXECUTION_DATE='2024-12-05T10:41:35.577441+00:00' AIRFLOW_CTX_TRY_NUMBER='1' AIRFLOW_CTX_DAG_RUN_ID='manual__2024-12-05T10:41:35.577441+00:00'
[2024-12-05T10:41:38.100+0000] {logging_mixin.py:190} INFO - Task instance is in running state
[2024-12-05T10:41:38.100+0000] {logging_mixin.py:190} INFO -  Previous state of the Task instance: queued
[2024-12-05T10:41:38.101+0000] {logging_mixin.py:190} INFO - Current task name:load_and_transform_data state:running start_date:2024-12-05 10:41:37.925767+00:00
[2024-12-05T10:41:38.102+0000] {logging_mixin.py:190} INFO - Dag name:bigquery_etl_dag and current dag run status:running
[2024-12-05T10:41:38.103+0000] {taskinstance.py:731} INFO - ::endgroup::
[2024-12-05T10:41:38.213+0000] {csv_to_bigquery.py:16} ERROR - Failed to upload data to assignment-arben.AssignmentDataset.Users: 'function' object has no attribute 'columns'
[2024-12-05T10:41:38.214+0000] {taskinstance.py:3311} ERROR - Task failed with exception
Traceback (most recent call last):
  File "/opt/airflow/dags/utils/csv_to_bigquery.py", line 12, in upload_to_bigquery
    job = client.load_table_from_dataframe(df, table_id, job_config=job_config)
          ^^^^^^^^^^^^^^^^^^^^^^^^^^^^^^^^^^^^^^^^^^^^^^^^^^^^^^^^^^^^^^^^^^^^^
  File "/home/airflow/.local/lib/python3.12/site-packages/google/cloud/bigquery/client.py", line 2768, in load_table_from_dataframe
    new_job_config.schema = _pandas_helpers.dataframe_to_bq_schema(
                            ^^^^^^^^^^^^^^^^^^^^^^^^^^^^^^^^^^^^^^^
  File "/home/airflow/.local/lib/python3.12/site-packages/google/cloud/bigquery/_pandas_helpers.py", line 422, in dataframe_to_bq_schema
    for column, dtype in list_columns_and_indexes(dataframe):
                         ^^^^^^^^^^^^^^^^^^^^^^^^^^^^^^^^^^^
  File "/home/airflow/.local/lib/python3.12/site-packages/google/cloud/bigquery/_pandas_helpers.py", line 342, in list_columns_and_indexes
    column_names = frozenset(dataframe.columns)
                             ^^^^^^^^^^^^^^^^^
AttributeError: 'function' object has no attribute 'columns'

During handling of the above exception, another exception occurred:

Traceback (most recent call last):
  File "/home/airflow/.local/lib/python3.12/site-packages/airflow/models/taskinstance.py", line 767, in _execute_task
    result = _execute_callable(context=context, **execute_callable_kwargs)
             ^^^^^^^^^^^^^^^^^^^^^^^^^^^^^^^^^^^^^^^^^^^^^^^^^^^^^^^^^^^^^
  File "/home/airflow/.local/lib/python3.12/site-packages/airflow/models/taskinstance.py", line 733, in _execute_callable
    return ExecutionCallableRunner(
           ^^^^^^^^^^^^^^^^^^^^^^^^
  File "/home/airflow/.local/lib/python3.12/site-packages/airflow/utils/operator_helpers.py", line 252, in run
    return self.func(*args, **kwargs)
           ^^^^^^^^^^^^^^^^^^^^^^^^^^
  File "/home/airflow/.local/lib/python3.12/site-packages/airflow/models/baseoperator.py", line 417, in wrapper
    return func(self, *args, **kwargs)
           ^^^^^^^^^^^^^^^^^^^^^^^^^^^
  File "/home/airflow/.local/lib/python3.12/site-packages/airflow/operators/python.py", line 238, in execute
    return_value = self.execute_callable()
                   ^^^^^^^^^^^^^^^^^^^^^^^
  File "/home/airflow/.local/lib/python3.12/site-packages/airflow/operators/python.py", line 256, in execute_callable
    return runner.run(*self.op_args, **self.op_kwargs)
           ^^^^^^^^^^^^^^^^^^^^^^^^^^^^^^^^^^^^^^^^^^^
  File "/home/airflow/.local/lib/python3.12/site-packages/airflow/utils/operator_helpers.py", line 252, in run
    return self.func(*args, **kwargs)
           ^^^^^^^^^^^^^^^^^^^^^^^^^^
  File "/opt/airflow/dags/bigquery_etl_dag.py", line 29, in load_and_transform_data
    upload_to_bigquery(users_df, users_table_id, credentials_path)
  File "/opt/airflow/dags/utils/csv_to_bigquery.py", line 17, in upload_to_bigquery
    raise AirflowFailException("BigQuery upload failed")
airflow.exceptions.AirflowFailException: BigQuery upload failed
[2024-12-05T10:41:38.249+0000] {logging_mixin.py:190} INFO - Task instance in failure state
[2024-12-05T10:41:38.250+0000] {logging_mixin.py:190} INFO - Task start:2024-12-05 10:41:37.925767+00:00 end:2024-12-05 10:41:38.249273+00:00 duration:0.323506
[2024-12-05T10:41:38.251+0000] {logging_mixin.py:190} INFO - Task:<Task(PythonOperator): load_and_transform_data> dag:<DAG: bigquery_etl_dag> dagrun:<DagRun bigquery_etl_dag @ 2024-12-05 10:41:35.577441+00:00: manual__2024-12-05T10:41:35.577441+00:00, state:running, queued_at: 2024-12-05 10:41:35.609202+00:00. externally triggered: True>
[2024-12-05T10:41:38.252+0000] {logging_mixin.py:190} INFO - Failure caused by BigQuery upload failed
[2024-12-05T10:41:38.253+0000] {taskinstance.py:1225} INFO - Immediate failure requested. Marking task as FAILED. dag_id=bigquery_etl_dag, task_id=load_and_transform_data, run_id=manual__2024-12-05T10:41:35.577441+00:00, execution_date=20241205T104135, start_date=20241205T104137, end_date=20241205T104138
[2024-12-05T10:41:38.268+0000] {warnings.py:112} WARNING - /home/***/.local/lib/python3.12/site-packages/***/utils/email.py:155: RemovedInAirflow3Warning: Fetching SMTP credentials from configuration variables will be deprecated in a future release. Please set credentials using a connection instead.
  send_mime_email(e_from=mail_from, e_to=recipients, mime_msg=msg, conn_id=conn_id, dryrun=dryrun)

[2024-12-05T10:41:38.269+0000] {configuration.py:1073} WARNING - section/key [smtp/smtp_user] not found in config
[2024-12-05T10:41:38.270+0000] {email.py:272} INFO - Email alerting: attempt 1
[2024-12-05T10:41:38.277+0000] {configuration.py:1073} WARNING - section/key [smtp/smtp_user] not found in config
[2024-12-05T10:41:38.278+0000] {email.py:272} INFO - Email alerting: attempt 1
[2024-12-05T10:41:38.280+0000] {taskinstance.py:1234} ERROR - Failed to send email to: ['arbenos20@gmail.com']
Traceback (most recent call last):
  File "/opt/airflow/dags/utils/csv_to_bigquery.py", line 12, in upload_to_bigquery
    job = client.load_table_from_dataframe(df, table_id, job_config=job_config)
          ^^^^^^^^^^^^^^^^^^^^^^^^^^^^^^^^^^^^^^^^^^^^^^^^^^^^^^^^^^^^^^^^^^^^^
  File "/home/airflow/.local/lib/python3.12/site-packages/google/cloud/bigquery/client.py", line 2768, in load_table_from_dataframe
    new_job_config.schema = _pandas_helpers.dataframe_to_bq_schema(
                            ^^^^^^^^^^^^^^^^^^^^^^^^^^^^^^^^^^^^^^^
  File "/home/airflow/.local/lib/python3.12/site-packages/google/cloud/bigquery/_pandas_helpers.py", line 422, in dataframe_to_bq_schema
    for column, dtype in list_columns_and_indexes(dataframe):
                         ^^^^^^^^^^^^^^^^^^^^^^^^^^^^^^^^^^^
  File "/home/airflow/.local/lib/python3.12/site-packages/google/cloud/bigquery/_pandas_helpers.py", line 342, in list_columns_and_indexes
    column_names = frozenset(dataframe.columns)
                             ^^^^^^^^^^^^^^^^^
AttributeError: 'function' object has no attribute 'columns'

During handling of the above exception, another exception occurred:

Traceback (most recent call last):
  File "/home/airflow/.local/lib/python3.12/site-packages/airflow/models/taskinstance.py", line 273, in _run_raw_task
    TaskInstance._execute_task_with_callbacks(
  File "/home/airflow/.local/lib/python3.12/site-packages/airflow/models/taskinstance.py", line 3159, in _execute_task_with_callbacks
    result = self._execute_task(context, task_orig)
             ^^^^^^^^^^^^^^^^^^^^^^^^^^^^^^^^^^^^^^
  File "/home/airflow/.local/lib/python3.12/site-packages/airflow/models/taskinstance.py", line 3183, in _execute_task
    return _execute_task(self, context, task_orig)
           ^^^^^^^^^^^^^^^^^^^^^^^^^^^^^^^^^^^^^^^
  File "/home/airflow/.local/lib/python3.12/site-packages/airflow/models/taskinstance.py", line 767, in _execute_task
    result = _execute_callable(context=context, **execute_callable_kwargs)
             ^^^^^^^^^^^^^^^^^^^^^^^^^^^^^^^^^^^^^^^^^^^^^^^^^^^^^^^^^^^^^
  File "/home/airflow/.local/lib/python3.12/site-packages/airflow/models/taskinstance.py", line 733, in _execute_callable
    return ExecutionCallableRunner(
           ^^^^^^^^^^^^^^^^^^^^^^^^
  File "/home/airflow/.local/lib/python3.12/site-packages/airflow/utils/operator_helpers.py", line 252, in run
    return self.func(*args, **kwargs)
           ^^^^^^^^^^^^^^^^^^^^^^^^^^
  File "/home/airflow/.local/lib/python3.12/site-packages/airflow/models/baseoperator.py", line 417, in wrapper
    return func(self, *args, **kwargs)
           ^^^^^^^^^^^^^^^^^^^^^^^^^^^
  File "/home/airflow/.local/lib/python3.12/site-packages/airflow/operators/python.py", line 238, in execute
    return_value = self.execute_callable()
                   ^^^^^^^^^^^^^^^^^^^^^^^
  File "/home/airflow/.local/lib/python3.12/site-packages/airflow/operators/python.py", line 256, in execute_callable
    return runner.run(*self.op_args, **self.op_kwargs)
           ^^^^^^^^^^^^^^^^^^^^^^^^^^^^^^^^^^^^^^^^^^^
  File "/home/airflow/.local/lib/python3.12/site-packages/airflow/utils/operator_helpers.py", line 252, in run
    return self.func(*args, **kwargs)
           ^^^^^^^^^^^^^^^^^^^^^^^^^^
  File "/opt/airflow/dags/bigquery_etl_dag.py", line 29, in load_and_transform_data
    upload_to_bigquery(users_df, users_table_id, credentials_path)
  File "/opt/airflow/dags/utils/csv_to_bigquery.py", line 17, in upload_to_bigquery
    raise AirflowFailException("BigQuery upload failed")
airflow.exceptions.AirflowFailException: BigQuery upload failed

During handling of the above exception, another exception occurred:

Traceback (most recent call last):
  File "/home/airflow/.local/lib/python3.12/site-packages/airflow/models/taskinstance.py", line 1442, in _email_alert
    send_email(task.email, subject, html_content)
  File "/home/airflow/.local/lib/python3.12/site-packages/airflow/utils/email.py", line 80, in send_email
    return backend(
           ^^^^^^^^
  File "/home/airflow/.local/lib/python3.12/site-packages/airflow/utils/email.py", line 155, in send_email_smtp
    send_mime_email(e_from=mail_from, e_to=recipients, mime_msg=msg, conn_id=conn_id, dryrun=dryrun)
  File "/home/airflow/.local/lib/python3.12/site-packages/airflow/utils/email.py", line 274, in send_mime_email
    smtp_conn = _get_smtp_connection(smtp_host, smtp_port, smtp_timeout, smtp_ssl)
                ^^^^^^^^^^^^^^^^^^^^^^^^^^^^^^^^^^^^^^^^^^^^^^^^^^^^^^^^^^^^^^^^^^
  File "/home/airflow/.local/lib/python3.12/site-packages/airflow/utils/email.py", line 318, in _get_smtp_connection
    return smtplib.SMTP(host=host, port=port, timeout=timeout)
           ^^^^^^^^^^^^^^^^^^^^^^^^^^^^^^^^^^^^^^^^^^^^^^^^^^^
  File "/usr/local/lib/python3.12/smtplib.py", line 255, in __init__
    (code, msg) = self.connect(host, port)
                  ^^^^^^^^^^^^^^^^^^^^^^^^
  File "/usr/local/lib/python3.12/smtplib.py", line 341, in connect
    self.sock = self._get_socket(host, port, self.timeout)
                ^^^^^^^^^^^^^^^^^^^^^^^^^^^^^^^^^^^^^^^^^^
  File "/usr/local/lib/python3.12/smtplib.py", line 312, in _get_socket
    return socket.create_connection((host, port), timeout,
           ^^^^^^^^^^^^^^^^^^^^^^^^^^^^^^^^^^^^^^^^^^^^^^^
  File "/usr/local/lib/python3.12/socket.py", line 865, in create_connection
    raise exceptions[0]
  File "/usr/local/lib/python3.12/socket.py", line 850, in create_connection
    sock.connect(sa)
OSError: [Errno 99] Cannot assign requested address

During handling of the above exception, another exception occurred:

Traceback (most recent call last):
  File "/home/airflow/.local/lib/python3.12/site-packages/airflow/models/taskinstance.py", line 1232, in _handle_failure
    task_instance.email_alert(error, failure_context["task"])
  File "/home/airflow/.local/lib/python3.12/site-packages/airflow/models/taskinstance.py", line 3605, in email_alert
    _email_alert(task_instance=self, exception=exception, task=task)
  File "/home/airflow/.local/lib/python3.12/site-packages/airflow/models/taskinstance.py", line 1444, in _email_alert
    send_email(task.email, subject, html_content_err)
  File "/home/airflow/.local/lib/python3.12/site-packages/airflow/utils/email.py", line 80, in send_email
    return backend(
           ^^^^^^^^
  File "/home/airflow/.local/lib/python3.12/site-packages/airflow/utils/email.py", line 155, in send_email_smtp
    send_mime_email(e_from=mail_from, e_to=recipients, mime_msg=msg, conn_id=conn_id, dryrun=dryrun)
  File "/home/airflow/.local/lib/python3.12/site-packages/airflow/utils/email.py", line 274, in send_mime_email
    smtp_conn = _get_smtp_connection(smtp_host, smtp_port, smtp_timeout, smtp_ssl)
                ^^^^^^^^^^^^^^^^^^^^^^^^^^^^^^^^^^^^^^^^^^^^^^^^^^^^^^^^^^^^^^^^^^
  File "/home/airflow/.local/lib/python3.12/site-packages/airflow/utils/email.py", line 318, in _get_smtp_connection
    return smtplib.SMTP(host=host, port=port, timeout=timeout)
           ^^^^^^^^^^^^^^^^^^^^^^^^^^^^^^^^^^^^^^^^^^^^^^^^^^^
  File "/usr/local/lib/python3.12/smtplib.py", line 255, in __init__
    (code, msg) = self.connect(host, port)
                  ^^^^^^^^^^^^^^^^^^^^^^^^
  File "/usr/local/lib/python3.12/smtplib.py", line 341, in connect
    self.sock = self._get_socket(host, port, self.timeout)
                ^^^^^^^^^^^^^^^^^^^^^^^^^^^^^^^^^^^^^^^^^^
  File "/usr/local/lib/python3.12/smtplib.py", line 312, in _get_socket
    return socket.create_connection((host, port), timeout,
           ^^^^^^^^^^^^^^^^^^^^^^^^^^^^^^^^^^^^^^^^^^^^^^^
  File "/usr/local/lib/python3.12/socket.py", line 865, in create_connection
    raise exceptions[0]
  File "/usr/local/lib/python3.12/socket.py", line 850, in create_connection
    sock.connect(sa)
OSError: [Errno 99] Cannot assign requested address
[2024-12-05T10:41:38.309+0000] {taskinstance.py:340} INFO - ::group::Post task execution logs
[2024-12-05T10:41:38.310+0000] {standard_task_runner.py:124} ERROR - Failed to execute job 118 for task load_and_transform_data (BigQuery upload failed; 739)
Traceback (most recent call last):
  File "/opt/airflow/dags/utils/csv_to_bigquery.py", line 12, in upload_to_bigquery
    job = client.load_table_from_dataframe(df, table_id, job_config=job_config)
          ^^^^^^^^^^^^^^^^^^^^^^^^^^^^^^^^^^^^^^^^^^^^^^^^^^^^^^^^^^^^^^^^^^^^^
  File "/home/airflow/.local/lib/python3.12/site-packages/google/cloud/bigquery/client.py", line 2768, in load_table_from_dataframe
    new_job_config.schema = _pandas_helpers.dataframe_to_bq_schema(
                            ^^^^^^^^^^^^^^^^^^^^^^^^^^^^^^^^^^^^^^^
  File "/home/airflow/.local/lib/python3.12/site-packages/google/cloud/bigquery/_pandas_helpers.py", line 422, in dataframe_to_bq_schema
    for column, dtype in list_columns_and_indexes(dataframe):
                         ^^^^^^^^^^^^^^^^^^^^^^^^^^^^^^^^^^^
  File "/home/airflow/.local/lib/python3.12/site-packages/google/cloud/bigquery/_pandas_helpers.py", line 342, in list_columns_and_indexes
    column_names = frozenset(dataframe.columns)
                             ^^^^^^^^^^^^^^^^^
AttributeError: 'function' object has no attribute 'columns'

During handling of the above exception, another exception occurred:

Traceback (most recent call last):
  File "/home/airflow/.local/lib/python3.12/site-packages/airflow/task/task_runner/standard_task_runner.py", line 117, in _start_by_fork
    ret = args.func(args, dag=self.dag)
          ^^^^^^^^^^^^^^^^^^^^^^^^^^^^^
  File "/home/airflow/.local/lib/python3.12/site-packages/airflow/cli/cli_config.py", line 49, in command
    return func(*args, **kwargs)
           ^^^^^^^^^^^^^^^^^^^^^
  File "/home/airflow/.local/lib/python3.12/site-packages/airflow/utils/cli.py", line 116, in wrapper
    return f(*args, **kwargs)
           ^^^^^^^^^^^^^^^^^^
  File "/home/airflow/.local/lib/python3.12/site-packages/airflow/cli/commands/task_command.py", line 483, in task_run
    task_return_code = _run_task_by_selected_method(args, _dag, ti)
                       ^^^^^^^^^^^^^^^^^^^^^^^^^^^^^^^^^^^^^^^^^^^^
  File "/home/airflow/.local/lib/python3.12/site-packages/airflow/cli/commands/task_command.py", line 256, in _run_task_by_selected_method
    return _run_raw_task(args, ti)
           ^^^^^^^^^^^^^^^^^^^^^^^
  File "/home/airflow/.local/lib/python3.12/site-packages/airflow/cli/commands/task_command.py", line 341, in _run_raw_task
    return ti._run_raw_task(
           ^^^^^^^^^^^^^^^^^
  File "/home/airflow/.local/lib/python3.12/site-packages/airflow/utils/session.py", line 97, in wrapper
    return func(*args, session=session, **kwargs)
           ^^^^^^^^^^^^^^^^^^^^^^^^^^^^^^^^^^^^^^
  File "/home/airflow/.local/lib/python3.12/site-packages/airflow/models/taskinstance.py", line 3005, in _run_raw_task
    return _run_raw_task(
           ^^^^^^^^^^^^^^
  File "/home/airflow/.local/lib/python3.12/site-packages/airflow/models/taskinstance.py", line 273, in _run_raw_task
    TaskInstance._execute_task_with_callbacks(
  File "/home/airflow/.local/lib/python3.12/site-packages/airflow/models/taskinstance.py", line 3159, in _execute_task_with_callbacks
    result = self._execute_task(context, task_orig)
             ^^^^^^^^^^^^^^^^^^^^^^^^^^^^^^^^^^^^^^
  File "/home/airflow/.local/lib/python3.12/site-packages/airflow/models/taskinstance.py", line 3183, in _execute_task
    return _execute_task(self, context, task_orig)
           ^^^^^^^^^^^^^^^^^^^^^^^^^^^^^^^^^^^^^^^
  File "/home/airflow/.local/lib/python3.12/site-packages/airflow/models/taskinstance.py", line 767, in _execute_task
    result = _execute_callable(context=context, **execute_callable_kwargs)
             ^^^^^^^^^^^^^^^^^^^^^^^^^^^^^^^^^^^^^^^^^^^^^^^^^^^^^^^^^^^^^
  File "/home/airflow/.local/lib/python3.12/site-packages/airflow/models/taskinstance.py", line 733, in _execute_callable
    return ExecutionCallableRunner(
           ^^^^^^^^^^^^^^^^^^^^^^^^
  File "/home/airflow/.local/lib/python3.12/site-packages/airflow/utils/operator_helpers.py", line 252, in run
    return self.func(*args, **kwargs)
           ^^^^^^^^^^^^^^^^^^^^^^^^^^
  File "/home/airflow/.local/lib/python3.12/site-packages/airflow/models/baseoperator.py", line 417, in wrapper
    return func(self, *args, **kwargs)
           ^^^^^^^^^^^^^^^^^^^^^^^^^^^
  File "/home/airflow/.local/lib/python3.12/site-packages/airflow/operators/python.py", line 238, in execute
    return_value = self.execute_callable()
                   ^^^^^^^^^^^^^^^^^^^^^^^
  File "/home/airflow/.local/lib/python3.12/site-packages/airflow/operators/python.py", line 256, in execute_callable
    return runner.run(*self.op_args, **self.op_kwargs)
           ^^^^^^^^^^^^^^^^^^^^^^^^^^^^^^^^^^^^^^^^^^^
  File "/home/airflow/.local/lib/python3.12/site-packages/airflow/utils/operator_helpers.py", line 252, in run
    return self.func(*args, **kwargs)
           ^^^^^^^^^^^^^^^^^^^^^^^^^^
  File "/opt/airflow/dags/bigquery_etl_dag.py", line 29, in load_and_transform_data
    upload_to_bigquery(users_df, users_table_id, credentials_path)
  File "/opt/airflow/dags/utils/csv_to_bigquery.py", line 17, in upload_to_bigquery
    raise AirflowFailException("BigQuery upload failed")
airflow.exceptions.AirflowFailException: BigQuery upload failed
[2024-12-05T10:41:38.377+0000] {local_task_job_runner.py:266} INFO - Task exited with return code 1
[2024-12-05T10:41:38.400+0000] {taskinstance.py:3895} INFO - 1 downstream tasks scheduled from follow-on schedule check
[2024-12-05T10:41:38.403+0000] {local_task_job_runner.py:245} INFO - ::endgroup::
